Traceback (most recent call last):
  File "/Users/andra/Library/Python/3.9/lib/python/site-packages/jupyter_cache/executors/utils.py", line 58, in single_nb_execution
    executenb(
  File "/Users/andra/Library/Python/3.9/lib/python/site-packages/nbclient/client.py", line 1305, in execute
    return NotebookClient(nb=nb, resources=resources, km=km, **kwargs).execute()
  File "/Users/andra/Library/Python/3.9/lib/python/site-packages/jupyter_core/utils/__init__.py", line 166, in wrapped
    return loop.run_until_complete(inner)
  File "/Library/Developer/CommandLineTools/Library/Frameworks/Python3.framework/Versions/3.9/lib/python3.9/asyncio/base_events.py", line 642, in run_until_complete
    return future.result()
  File "/Users/andra/Library/Python/3.9/lib/python/site-packages/nbclient/client.py", line 705, in async_execute
    await self.async_execute_cell(
  File "/Users/andra/Library/Python/3.9/lib/python/site-packages/nbclient/client.py", line 1058, in async_execute_cell
    await self._check_raise_for_error(cell, cell_index, exec_reply)
  File "/Users/andra/Library/Python/3.9/lib/python/site-packages/nbclient/client.py", line 914, in _check_raise_for_error
    raise CellExecutionError.from_cell_and_msg(cell, exec_reply_content)
nbclient.exceptions.CellExecutionError: An error occurred while executing the following cell:
------------------
url = index+'/index/entries/all'
headers = {'accept': 'application/json'}

response = requests.get(url, headers=headers)
data = response.json()

df = pd.DataFrame(data)
df
------------------


[0;31m---------------------------------------------------------------------------[0m
[0;31mNameError[0m                                 Traceback (most recent call last)
Cell [0;32mIn[2], line 1[0m
[0;32m----> 1[0m url [38;5;241m=[39m [43mindex[49m[38;5;241m+[39m[38;5;124m'[39m[38;5;124m/index/entries/all[39m[38;5;124m'[39m
[1;32m      2[0m headers [38;5;241m=[39m {[38;5;124m'[39m[38;5;124maccept[39m[38;5;124m'[39m: [38;5;124m'[39m[38;5;124mapplication/json[39m[38;5;124m'[39m}
[1;32m      4[0m response [38;5;241m=[39m requests[38;5;241m.[39mget(url, headers[38;5;241m=[39mheaders)

[0;31mNameError[0m: name 'index' is not defined

